<?xml version="1.0" ?>
<!-- =================================================================================== -->
<!-- |    This document was autogenerated by xacro from /home/mh/robogym_ws/src/Ur_hrihand/ur_hrihand_gazebo/urdf/ur3_robot_hri_hand.urdf.xacro | -->
<!-- |    EDITING THIS FILE BY HAND IS NOT RECOMMENDED                                 | -->
<!-- =================================================================================== -->
<robot name="ur3">
    <!-- common stuff -->
    <!--xacro:include filename="$(find ur_description)/urdf/common.gazebo.xacro" /-->
    <!--
  Author: Felix Messmer
-->
    <!-- measured from model -->
    <link name="world" />
    <joint name="world_joint" type="fixed">
        <parent link="world" />
        <child link="base_link" />
        <origin rpy="0 0 0" xyz="0 -0.7 0.75" />
    </joint>
    <link name="base_link">
        <visual>
            <geometry>
                <mesh filename="package://husky_ur3_gazebo/meshes/ur3/visual/base.dae" />
            </geometry>
            <material name="LightGrey">
                <color rgba="0.7 0.7 0.7 1.0" />
            </material>
        </visual>
        <collision>
            <geometry>
                <mesh filename="package://husky_ur3_gazebo/meshes/ur3/collision/base.stl" />
            </geometry>
        </collision>
        <inertial>
            <mass value="2.0" />
            <origin rpy="0 0 0" xyz="0.0 0.0 0.0" />
            <inertia ixx="0.0030531654454" ixy="0.0" ixz="0.0" iyy="0.0030531654454" iyz="0.0" izz="0.005625" />
        </inertial>
    </link>
    <joint name="shoulder_pan_joint" type="revolute">
        <parent link="base_link" />
        <child link="shoulder_link" />
        <origin rpy="0.0 0.0 0.0" xyz="0.0 0.0 0.1519" />
        <axis xyz="0 0 1" />
        <limit effort="330.0" lower="-3.141592653589793" upper="3.141592653589793" velocity="2.16" />
        <dynamics damping="0.0" friction="0.0" />
    </joint>
    <link name="shoulder_link">
        <visual>
            <geometry>
                <mesh filename="package://husky_ur3_gazebo/meshes/ur3/visual/shoulder.dae" />
            </geometry>
            <material name="LightGrey">
                <color rgba="0.7 0.7 0.7 1.0" />
            </material>
        </visual>
        <collision>
            <geometry>
                <mesh filename="package://husky_ur3_gazebo/meshes/ur3/collision/shoulder.stl" />
            </geometry>
        </collision>
        <inertial>
            <mass value="2.0" />
            <origin rpy="0 0 0" xyz="0.0 0.0 0.0" />
            <inertia ixx="0.008093163429399999" ixy="0.0" ixz="0.0" iyy="0.008093163429399999" iyz="0.0" izz="0.005625" />
        </inertial>
    </link>
    <joint name="shoulder_lift_joint" type="revolute">
        <parent link="shoulder_link" />
        <child link="upper_arm_link" />
        <origin rpy="0.0 1.5707963267948966 0.0" xyz="0.0 0.1198 0.0" />
        <axis xyz="0 1 0" />
        <limit effort="330.0" lower="-3.141592653589793" upper="3.141592653589793" velocity="2.16" />
        <dynamics damping="0.0" friction="0.0" />
    </joint>
    <link name="upper_arm_link">
        <visual>
            <geometry>
                <mesh filename="package://husky_ur3_gazebo/meshes/ur3/visual/upperarm.dae" />
            </geometry>
            <material name="LightGrey">
                <color rgba="0.7 0.7 0.7 1.0" />
            </material>
        </visual>
        <collision>
            <geometry>
                <mesh filename="package://husky_ur3_gazebo/meshes/ur3/collision/upperarm.stl" />
            </geometry>
        </collision>
        <inertial>
            <mass value="3.42" />
            <origin rpy="0 0 0" xyz="0.0 0.0 0.121825" />
            <inertia ixx="0.021728483221103233" ixy="0.0" ixz="0.0" iyy="0.021728483221103233" iyz="0.0" izz="0.00961875" />
        </inertial>
    </link>
    <joint name="elbow_joint" type="revolute">
        <parent link="upper_arm_link" />
        <child link="forearm_link" />
        <origin rpy="0.0 0.0 0.0" xyz="0.0 -0.0925 0.24365" />
        <axis xyz="0 1 0" />
        <limit effort="150.0" lower="-2.618002653589793" upper="3.141592653589793" velocity="3.15" />
        <dynamics damping="0.0" friction="0.0" />
    </joint>
    <link name="forearm_link">
        <visual>
            <geometry>
                <mesh filename="package://husky_ur3_gazebo/meshes/ur3/visual/forearm.dae" />
            </geometry>
            <material name="LightGrey">
                <color rgba="0.7 0.7 0.7 1.0" />
            </material>
        </visual>
        <collision>
            <geometry>
                <mesh filename="package://husky_ur3_gazebo/meshes/ur3/collision/forearm.stl" />
            </geometry>
        </collision>
        <inertial>
            <mass value="1.26" />
            <origin rpy="0 0 0" xyz="0.0 0.0 0.106625" />
            <inertia ixx="0.006546806443776375" ixy="0.0" ixz="0.0" iyy="0.006546806443776375" iyz="0.0" izz="0.00354375" />
        </inertial>
    </link>
    <joint name="wrist_1_joint" type="revolute">
        <parent link="forearm_link" />
        <child link="wrist_1_link" />
        <origin rpy="0.0 1.5707963267948966 0.0" xyz="0.0 0.0 0.21325" />
        <axis xyz="0 1 0" />
        <limit effort="54.0" lower="-3.141592653589793" upper="3.141592653589793" velocity="3.2" />
        <dynamics damping="0.0" friction="0.0" />
    </joint>
    <link name="wrist_1_link">
        <visual>
            <geometry>
                <mesh filename="package://husky_ur3_gazebo/meshes/ur3/visual/wrist1.dae" />
            </geometry>
            <material name="LightGrey">
                <color rgba="0.7 0.7 0.7 1.0" />
            </material>
        </visual>
        <collision>
            <geometry>
                <mesh filename="package://husky_ur3_gazebo/meshes/ur3/collision/wrist1.stl" />
            </geometry>
        </collision>
        <inertial>
            <mass value="0.8" />
            <origin rpy="0 0 0" xyz="0.0 0.08505 0.0" />
            <inertia ixx="0.002084999166" ixy="0.0" ixz="0.0" iyy="0.002084999166" iyz="0.0" izz="0.00225" />
        </inertial>
    </link>
    <joint name="wrist_2_joint" type="revolute">
        <parent link="wrist_1_link" />
        <child link="wrist_2_link" />
        <origin rpy="0.0 0.0 0.0" xyz="0.0 0.08505 0.0" />
        <axis xyz="0 0 1" />
        <limit effort="54.0" lower="-3.141592653589793" upper="3.141592653589793" velocity="3.2" />
        <dynamics damping="0.0" friction="0.0" />
    </joint>
    <link name="wrist_2_link">
        <visual>
            <geometry>
                <mesh filename="package://husky_ur3_gazebo/meshes/ur3/visual/wrist2.dae" />
            </geometry>
            <material name="LightGrey">
                <color rgba="0.7 0.7 0.7 1.0" />
            </material>
        </visual>
        <collision>
            <geometry>
                <mesh filename="package://husky_ur3_gazebo/meshes/ur3/collision/wrist2.stl" />
            </geometry>
        </collision>
        <inertial>
            <mass value="0.8" />
            <origin rpy="0 0 0" xyz="0.0 0.0 0.08535" />
            <inertia ixx="0.002084999166" ixy="0.0" ixz="0.0" iyy="0.002084999166" iyz="0.0" izz="0.00225" />
        </inertial>
    </link>
    <joint name="wrist_3_joint" type="revolute">
        <parent link="wrist_2_link" />
        <child link="wrist_3_link" />
        <origin rpy="0.0 0.0 0.0" xyz="0.0 0.0 0.08535" />
        <axis xyz="0 1 0" />
        <limit effort="54.0" lower="-3.141592653589793" upper="3.141592653589793" velocity="3.2" />
        <dynamics damping="0.0" friction="0.0" />
    </joint>
    <link name="wrist_3_link">
        <visual>
            <geometry>
                <mesh filename="package://husky_ur3_gazebo/meshes/ur3/visual/wrist3.dae" />
            </geometry>
            <material name="LightGrey">
                <color rgba="0.7 0.7 0.7 1.0" />
            </material>
        </visual>
        <collision>
            <geometry>
                <mesh filename="package://husky_ur3_gazebo/meshes/ur3/collision/wrist3.stl" />
            </geometry>
        </collision>
        <inertial>
            <mass value="0.35" />
            <origin rpy="1.5707963267948966 0 0" xyz="0.0 0.0619 0.0" />
            <inertia ixx="0.00013626661215999998" ixy="0.0" ixz="0.0" iyy="0.00013626661215999998" iyz="0.0" izz="0.0001792" />
        </inertial>
    </link>
    <!-- 
    <joint name="${prefix}ee_fixed_joint" type="fixed">
      <parent link="${prefix}wrist_3_link" />
      <child link = "${prefix}gripper_link" />
      <origin xyz="0.0 0.0 0.0" rpy="0.0 0.0 ${pi/2.0}" />
    </joint> -->
    <link name="gripper_link">
        <inertial>
            <origin rpy="0 0 0" xyz="0 0 0" />
            <mass value="0.3" />
            <inertia ixx="0.1" ixy="0" ixz="0" iyy="0.1" iyz="0" izz="0.1" />
        </inertial>
        <visual>
            <origin rpy="1.5707963267948966 0 -1.5707963267948966" xyz="0.008 0 0.115" />
            <geometry>
                <mesh filename="package://husky_ur3_gazebo/meshes/hri_hand.stl" />
            </geometry>
            <material name="Cyan">
                <color rgba="0 1.0 1.0 1.0" />
            </material>
        </visual>
        <collision>
            <origin rpy="1.5707963267948966 0 -1.5707963267948966" xyz="0.008 0 0.115" />
            <geometry>
                <mesh filename="package://husky_ur3_gazebo/meshes/hri_hand.stl" />
            </geometry>
        </collision>
    </link>
    <joint name="grip_joint" type="fixed">
        <parent link="gripper_link" />
        <child link="grip_point" />
        <origin rpy="0.0 0.0 0" xyz="0.015 0.0 0.185" />
    </joint>
    <link name="grip_point">
        <visual>
            <origin rpy="0 0 0" xyz="0 0 0" />
            <geometry>
                <box size="0.01 0.05 0.03" />
            </geometry>
        </visual>
        <collision>
            <origin rpy="0 0 0" xyz="0 0 0" />
            <geometry>
                <box size="0.01 0.05 0.03" />
            </geometry>
        </collision>
        <inertial>
            <mass value="0.1" />
            <origin xyz="0 0 0" rpy="0 0 0" />
            <inertia ixx="0.03" iyy="0.03" izz="0.03" ixy="0.0" ixz="0.0" iyz="0.0" />
        </inertial>
    </link>
    <transmission name="shoulder_pan_trans">
        <type>transmission_interface/SimpleTransmission</type>
        <joint name="shoulder_pan_joint">
            <hardwareInterface>hardware_interface/PositionJointInterface</hardwareInterface>
        </joint>
        <actuator name="shoulder_pan_motor">
            <mechanicalReduction>1</mechanicalReduction>
            <hardwareInterface>hardware_interface/PositionJointInterface</hardwareInterface>
        </actuator>
    </transmission>
    <transmission name="shoulder_lift_trans">
        <type>transmission_interface/SimpleTransmission</type>
        <joint name="shoulder_lift_joint">
            <hardwareInterface>hardware_interface/PositionJointInterface</hardwareInterface>
        </joint>
        <actuator name="shoulder_lift_motor">
            <mechanicalReduction>1</mechanicalReduction>
            <hardwareInterface>hardware_interface/PositionJointInterface</hardwareInterface>
        </actuator>
    </transmission>
    <transmission name="elbow_trans">
        <type>transmission_interface/SimpleTransmission</type>
        <joint name="elbow_joint">
            <hardwareInterface>hardware_interface/PositionJointInterface</hardwareInterface>
        </joint>
        <actuator name="elbow_motor">
            <mechanicalReduction>1</mechanicalReduction>
            <hardwareInterface>hardware_interface/PositionJointInterface</hardwareInterface>
        </actuator>
    </transmission>
    <transmission name="wrist_1_trans">
        <type>transmission_interface/SimpleTransmission</type>
        <joint name="wrist_1_joint">
            <hardwareInterface>hardware_interface/PositionJointInterface</hardwareInterface>
        </joint>
        <actuator name="wrist_1_motor">
            <mechanicalReduction>1</mechanicalReduction>
            <hardwareInterface>hardware_interface/PositionJointInterface</hardwareInterface>
        </actuator>
    </transmission>
    <transmission name="wrist_2_trans">
        <type>transmission_interface/SimpleTransmission</type>
        <joint name="wrist_2_joint">
            <hardwareInterface>hardware_interface/PositionJointInterface</hardwareInterface>
        </joint>
        <actuator name="wrist_2_motor">
            <mechanicalReduction>1</mechanicalReduction>
            <hardwareInterface>hardware_interface/PositionJointInterface</hardwareInterface>
        </actuator>
    </transmission>
    <transmission name="wrist_3_trans">
        <type>transmission_interface/SimpleTransmission</type>
        <joint name="wrist_3_joint">
            <hardwareInterface>hardware_interface/PositionJointInterface</hardwareInterface>
        </joint>
        <actuator name="wrist_3_motor">
            <mechanicalReduction>1</mechanicalReduction>
            <hardwareInterface>hardware_interface/PositionJointInterface</hardwareInterface>
        </actuator>
    </transmission>
    <gazebo reference="shoulder_link">
        <selfCollide>true</selfCollide>
        <plugin name="gazebo_ros_control">
            <robotNamespace>/</robotNamespace>
        </plugin>
    </gazebo>
    <gazebo reference="upper_arm_link">
        <selfCollide>true</selfCollide>
    </gazebo>
    <gazebo reference="forearm_link">
        <selfCollide>true</selfCollide>
    </gazebo>
    <gazebo reference="wrist_1_link">
        <selfCollide>true</selfCollide>
    </gazebo>
    <gazebo reference="wrist_3_link">
        <selfCollide>true</selfCollide>
    </gazebo>
    <gazebo reference="wrist_2_link">
        <selfCollide>true</selfCollide>
    </gazebo>
    <gazebo reference="ee_link">
        <selfCollide>true</selfCollide>
    </gazebo>
    <!-- ROS ur3_base_link to UR 'Base' Coordinates transform -->
    <link name="base" />
    <joint name="ur3_base_link-base_fixed_joint" type="fixed">
        <!-- NOTE: this rotation is only needed as long as ur3_base_link itself is
                 not corrected wrt the real robot (ie: rotated over 180
                 degrees)
      -->
        <origin rpy="0 0 -3.141592653589793" xyz="0 0 0" />
        <parent link="base_link" />
        <child link="base" />
    </joint>
    <!-- Frame coincident with all-zeros TCP on UR controller -->
    <!-- <link name="${prefix}tool0"/> -->
    <joint name="wrist_3_link-tool0_fixed_joint" type="fixed">
        <origin rpy="-1.5707963267948966 1.5707963267948966 0" xyz="0 0.0819 0" />
        <parent link="wrist_3_link" />
        <child link="gripper_link" />
    </joint>
    <!-- camera body, with origin at bottom screw mount -->
    <joint name="g_camera_joint" type="fixed">
        <origin rpy="0 -1.5707963267948966 0" xyz="-0.07 0.0 0.00" />
        <parent link="gripper_link" />
        <child link="g_camera_bottom_screw_frame" />
    </joint>
    <link name="g_camera_bottom_screw_frame" />
    <joint name="g_camera_link_joint" type="fixed">
        <origin rpy="0 0 0" xyz="0.010600000000000002 0.0175 0.0125" />
        <parent link="g_camera_bottom_screw_frame" />
        <child link="g_camera_link" />
    </joint>
    <link name="g_camera_link">
        <visual>
            <!-- the mesh origin is at front plate in betw`n the two infrared camera axes -->
            <origin rpy="1.5707963267948966 0 1.5707963267948966" xyz="0.0043 -0.0175 0" />
            <geometry>
                <!-- <box size="${d435_cam_width} ${d435_cam_height} ${d435_cam_depth}"/> -->
                <mesh filename="package://realsense2_description/meshes/d435.dae" />
            </geometry>
            <material name="white">
                <color rgba="0 0 0" />
            </material>
        </visual>
        <collision>
            <origin rpy="0 0 0" xyz="0 -0.0175 0" />
            <geometry>
                <box size="0.02505 0.09 0.025" />
            </geometry>
        </collision>
        <inertial>
            <!-- The following are not reliable values, and should not be used for modeling -->
            <mass value="0.072" />
            <origin xyz="0 0 0" rpy="0 0 0" />
            <inertia ixx="0.003881243" ixy="0.0" ixz="0.0" iyy="0.000498940" iyz="0.0" izz="0.003879257" />
        </inertial>
    </link>
    <!-- camera depth joints and links -->
    <joint name="g_camera_depth_joint" type="fixed">
        <origin rpy="0 0 0" xyz="0 0 0" />
        <parent link="g_camera_link" />
        <child link="g_camera_depth_frame" />
    </joint>
    <link name="g_camera_depth_frame" />
    <joint name="g_camera_depth_optical_joint" type="fixed">
        <origin rpy="-1.5707963267948966 0 -1.5707963267948966" xyz="0 0 0" />
        <parent link="g_camera_depth_frame" />
        <child link="g_camera_depth_optical_frame" />
    </joint>
    <link name="g_camera_depth_optical_frame" />
    <!-- camera left IR joints and links -->
    <joint name="g_camera_infra1_joint" type="fixed">
        <origin rpy="0 0 0" xyz="0 0.0 0" />
        <parent link="g_camera_link" />
        <child link="g_camera_infra1_frame" />
    </joint>
    <link name="g_camera_infra1_frame" />
    <joint name="g_camera_infra1_optical_joint" type="fixed">
        <origin rpy="-1.5707963267948966 0 -1.5707963267948966" xyz="0 0 0" />
        <parent link="g_camera_infra1_frame" />
        <child link="g_camera_infra1_optical_frame" />
    </joint>
    <link name="g_camera_infra1_optical_frame" />
    <!-- camera right IR joints and links -->
    <joint name="g_camera_infra2_joint" type="fixed">
        <origin rpy="0 0 0" xyz="0 -0.05 0" />
        <parent link="g_camera_link" />
        <child link="g_camera_infra2_frame" />
    </joint>
    <link name="g_camera_infra2_frame" />
    <joint name="g_camera_infra2_optical_joint" type="fixed">
        <origin rpy="-1.5707963267948966 0 -1.5707963267948966" xyz="0 0 0" />
        <parent link="g_camera_infra2_frame" />
        <child link="g_camera_infra2_optical_frame" />
    </joint>
    <link name="g_camera_infra2_optical_frame" />
    <!-- camera color joints and links -->
    <joint name="g_camera_color_joint" type="fixed">
        <origin rpy="0 0 0" xyz="0 0.015 0" />
        <parent link="g_camera_link" />
        <child link="g_camera_color_frame" />
    </joint>
    <link name="g_camera_color_frame" />
    <joint name="g_camera_color_optical_joint" type="fixed">
        <origin rpy="-1.5707963267948966 0 -1.5707963267948966" xyz="0 0 0" />
        <parent link="g_camera_color_frame" />
        <child link="g_camera_color_optical_frame" />
    </joint>
    <link name="g_camera_color_optical_frame" />
    <!--
    <xacro:if value="$(arg add_plug)">
      <xacro:usb_plug parent="${name}_link" name="${name}_usb_plug">
        <origin xyz="${d435_cam_mount_from_center_offset - 0.02095} ${-d435_cam_depth_py - 0.0353} 0" rpy="0 0 0"/>
      </xacro:usb_plug>
    </xacro:if>-->
    <gazebo reference="g_camera_link">
        <sensor name="g_camera" type="depth">
            <always_on>1</always_on>
            <visualize>true</visualize>
            <camera>
                <horizontal_fov>1.0471975511965976</horizontal_fov>
                <image>
                    <width>640</width>
                    <height>480</height>
                    <format>R8G8B8</format>
                </image>
                <depth_camera />
                <clip>
                    <near>0.11</near>
                    <far>10</far>
                </clip>
            </camera>
            <plugin filename="libgazebo_ros_openni_kinect.so" name="g_camera_controller">
                <alwaysOn>true</alwaysOn>
                <updateRate>20.0</updateRate>
                <cameraName>g_d435</cameraName>
                <frameName>g_camera_depth_optical_frame</frameName>
                <imageTopicName>rgb/g_image_raw</imageTopicName>
                <depthImageTopicName>depth/g_image_raw</depthImageTopicName>
                <pointCloudTopicName>depth/g_points</pointCloudTopicName>
                <cameraInfoTopicName>rgb/camera_info</cameraInfoTopicName>
                <depthImageCameraInfoTopicName>depth/camera_info</depthImageCameraInfoTopicName>
                <pointCloudCutoff>0.4</pointCloudCutoff>
                <hackBaseline>0.07</hackBaseline>
                <distortionK1>0.0</distortionK1>
                <distortionK2>0.0</distortionK2>
                <distortionK3>0.0</distortionK3>
                <distortionT1>0.0</distortionT1>
                <distortionT2>0.0</distortionT2>
                <CxPrime>0.0</CxPrime>
                <Cx>0.0</Cx>
                <Cy>0.0</Cy>
                <focalLength>0.0</focalLength>
            </plugin>
        </sensor>
    </gazebo>
    <!-- Configure self collision properties per link -->
    <gazebo reference="shoulder_link">
        <selfCollide>true</selfCollide>
    </gazebo>
    <gazebo reference="upper_arm_link">
        <selfCollide>true</selfCollide>
    </gazebo>
    <gazebo reference="forearm_link">
        <selfCollide>true</selfCollide>
    </gazebo>
    <gazebo reference="wrist_1_link">
        <selfCollide>true</selfCollide>
    </gazebo>
    <gazebo reference="wrist_3_link">
        <selfCollide>true</selfCollide>
    </gazebo>
    <gazebo reference="wrist_2_link">
        <selfCollide>true</selfCollide>
    </gazebo>
    <gazebo reference="gripper_link">
        <selfCollide>true</selfCollide>
    </gazebo>
    <!--
    Inject Gazebo ROS Control plugin, which allows us to use ros_control
    controllers to control the virtual robot hw.
  -->
    <gazebo>
        <plugin filename="libgazebo_ros_control.so" name="ros_control">
            <!--robotNamespace>/</robotNamespace-->
            <!--robotSimType>gazebo_ros_control/DefaultRobotHWSim</robotSimType-->
        </plugin>
    </gazebo>
    <!-- Collision sensors on all links -->
    <gazebo reference="shoulder_link">
        <sensor name="shoulder_link_contact" type="contact">
            <update_rate>50</update_rate>
            <always_on>true</always_on>
            <contact>
                <collision>shoulder_link_collision</collision>
            </contact>
            <plugin filename="libgazebo_ros_bumper.so" name="ros_bumper_0">
                <bumperTopicName>shoulder_collision</bumperTopicName>
                <frameName>shoulder_link</frameName>
            </plugin>
        </sensor>
    </gazebo>
    <gazebo reference="upper_arm_link">
        <sensor name="upper_arm_link_contact" type="contact">
            <update_rate>50</update_rate>
            <always_on>true</always_on>
            <contact>
                <collision>upper_arm_link_collision</collision>
            </contact>
            <plugin filename="libgazebo_ros_bumper.so" name="ros_bumper_1">
                <bumperTopicName>upper_arm_collision</bumperTopicName>
                <frameName>upper_arm_link</frameName>
            </plugin>
        </sensor>
    </gazebo>
    <gazebo reference="forearm_link">
        <sensor name="forearm_link_contact" type="contact">
            <update_rate>50</update_rate>
            <always_on>true</always_on>
            <contact>
                <collision>forearm_link_collision</collision>
            </contact>
            <plugin filename="libgazebo_ros_bumper.so" name="ros_bumper_2">
                <bumperTopicName>forearm_collision</bumperTopicName>
                <frameName>forearm_link</frameName>
            </plugin>
        </sensor>
    </gazebo>
    <gazebo reference="wrist_1_link">
        <sensor name="wrist_1_link_contact" type="contact">
            <update_rate>50</update_rate>
            <always_on>true</always_on>
            <contact>
                <collision>wrist_1_link_collision</collision>
            </contact>
            <plugin filename="libgazebo_ros_bumper.so" name="ros_bumper_3">
                <bumperTopicName>wrist_1_collision</bumperTopicName>
                <frameName>wrist_1_link</frameName>
            </plugin>
        </sensor>
    </gazebo>
    <gazebo reference="wrist_2_link">
        <sensor name="wrist_2_link_contact" type="contact">
            <update_rate>50</update_rate>
            <always_on>true</always_on>
            <contact>
                <collision>wrist_2_link_collision</collision>
            </contact>
            <plugin filename="libgazebo_ros_bumper.so" name="ros_bumper_4">
                <bumperTopicName>wrist_2_collision</bumperTopicName>
                <frameName>wrist_2_link</frameName>
            </plugin>
        </sensor>
    </gazebo>
    <gazebo reference="wrist_3_link">
        <sensor name="wrist_3_link_contact" type="contact">
            <update_rate>50</update_rate>
            <always_on>true</always_on>
            <contact>
                <collision>wrist_3_link_collision</collision>
            </contact>
            <plugin filename="libgazebo_ros_bumper.so" name="ros_bumper_5">
                <bumperTopicName>wrist_3_collision</bumperTopicName>
                <frameName>wrist_3_link</frameName>
            </plugin>
        </sensor>
    </gazebo>
    <!--add virtual contact sensor-->
    <gazebo reference="gripper_link">
        <sensor name="gripper_link_collision" type="contact">
            <update_rate>50</update_rate>
            <always_on>true</always_on>
            <contact>
                <collision>wrist_3_link_fixed_joint_lump__gripper_link_collision_1</collision>
            </contact>
            <plugin filename="libgazebo_ros_bumper.so" name="ros_bumper_6">
                <bumperTopicName>gripper_link_collision</bumperTopicName>
                <frameName>gripper_link_collision</frameName>
            </plugin>
        </sensor>
    </gazebo>
    <gazebo reference="grip_point">
        <sensor name="grip_point_contact" type="contact">
            <update_rate>50</update_rate>
            <always_on>true</always_on>
            <contact>
                <collision>wrist_3_link_fixed_joint_lump__grip_point_collision_3</collision>
            </contact>
            <plugin filename="libgazebo_ros_bumper.so" name="ros_bumper_7">
                <bumperTopicName>grip_point_collision</bumperTopicName>
                <frameName>grip_point_collision</frameName>
            </plugin>
        </sensor>
    </gazebo>
</robot>

